[2022-10-05 23:17:39,632] {taskinstance.py:1037} INFO - Dependencies all met for <TaskInstance: dag_combustivel.create_cluster scheduled__2018-07-01T00:00:00+00:00 [queued]>
[2022-10-05 23:17:39,643] {taskinstance.py:1037} INFO - Dependencies all met for <TaskInstance: dag_combustivel.create_cluster scheduled__2018-07-01T00:00:00+00:00 [queued]>
[2022-10-05 23:17:39,644] {taskinstance.py:1243} INFO - 
--------------------------------------------------------------------------------
[2022-10-05 23:17:39,645] {taskinstance.py:1244} INFO - Starting attempt 2 of 2
[2022-10-05 23:17:39,645] {taskinstance.py:1245} INFO - 
--------------------------------------------------------------------------------
[2022-10-05 23:17:39,657] {taskinstance.py:1264} INFO - Executing <Task(DataprocCreateClusterOperator): create_cluster> on 2018-07-01 00:00:00+00:00
[2022-10-05 23:17:39,662] {standard_task_runner.py:52} INFO - Started process 6768 to run task
[2022-10-05 23:17:39,666] {standard_task_runner.py:76} INFO - Running: ['***', 'tasks', 'run', 'dag_combustivel', 'create_cluster', 'scheduled__2018-07-01T00:00:00+00:00', '--job-id', '158', '--raw', '--subdir', 'DAGS_FOLDER/dag_combustive.py', '--cfg-path', '/tmp/tmpfawpgjvf', '--error-file', '/tmp/tmp2ksd7yu4']
[2022-10-05 23:17:39,668] {standard_task_runner.py:77} INFO - Job 158: Subtask create_cluster
[2022-10-05 23:17:39,744] {logging_mixin.py:109} INFO - Running <TaskInstance: dag_combustivel.create_cluster scheduled__2018-07-01T00:00:00+00:00 [running]> on host 1445d51ba90b
[2022-10-05 23:17:39,825] {taskinstance.py:1431} INFO - Exporting the following env vars:
AIRFLOW_CTX_DAG_OWNER=***
AIRFLOW_CTX_DAG_ID=dag_combustivel
AIRFLOW_CTX_TASK_ID=create_cluster
AIRFLOW_CTX_EXECUTION_DATE=2018-07-01T00:00:00+00:00
AIRFLOW_CTX_DAG_RUN_ID=scheduled__2018-07-01T00:00:00+00:00
[2022-10-05 23:17:39,829] {dataproc.py:625} INFO - Creating cluster: stack-data-pipeline
[2022-10-05 23:25:17,460] {taskinstance.py:1718} ERROR - Task failed with exception
Traceback (most recent call last):
  File "/home/airflow/.local/lib/python3.7/site-packages/google/api_core/grpc_helpers.py", line 67, in error_remapped_callable
    return callable_(*args, **kwargs)
  File "/home/airflow/.local/lib/python3.7/site-packages/grpc/_channel.py", line 946, in __call__
    return _end_unary_response_blocking(state, call, False, None)
  File "/home/airflow/.local/lib/python3.7/site-packages/grpc/_channel.py", line 849, in _end_unary_response_blocking
    raise _InactiveRpcError(state)
grpc._channel._InactiveRpcError: <_InactiveRpcError of RPC that terminated with:
	status = StatusCode.DEADLINE_EXCEEDED
	details = "Deadline Exceeded"
	debug_error_string = "{"created":"@1665012317.390874258","description":"Error received from peer ipv4:142.250.78.202:443","file":"src/core/lib/surface/call.cc","file_line":903,"grpc_message":"Deadline Exceeded","grpc_status":4}"
>

The above exception was the direct cause of the following exception:

Traceback (most recent call last):
  File "/home/airflow/.local/lib/python3.7/site-packages/airflow/models/taskinstance.py", line 1334, in _run_raw_task
    self._execute_task_with_callbacks(context)
  File "/home/airflow/.local/lib/python3.7/site-packages/airflow/models/taskinstance.py", line 1460, in _execute_task_with_callbacks
    result = self._execute_task(context, self.task)
  File "/home/airflow/.local/lib/python3.7/site-packages/airflow/models/taskinstance.py", line 1516, in _execute_task
    result = execute_callable(context=context)
  File "/home/airflow/.local/lib/python3.7/site-packages/airflow/providers/google/cloud/operators/dataproc.py", line 639, in execute
    cluster = self._create_cluster(hook)
  File "/home/airflow/.local/lib/python3.7/site-packages/airflow/providers/google/cloud/operators/dataproc.py", line 568, in _create_cluster
    cluster = operation.result()
  File "/home/airflow/.local/lib/python3.7/site-packages/google/api_core/future/polling.py", line 130, in result
    self._blocking_poll(timeout=timeout, **kwargs)
  File "/home/airflow/.local/lib/python3.7/site-packages/google/api_core/future/polling.py", line 108, in _blocking_poll
    retry_(self._done_or_raise)(**kwargs)
  File "/home/airflow/.local/lib/python3.7/site-packages/google/api_core/retry.py", line 291, in retry_wrapped_func
    on_error=on_error,
  File "/home/airflow/.local/lib/python3.7/site-packages/google/api_core/retry.py", line 189, in retry_target
    return target()
  File "/home/airflow/.local/lib/python3.7/site-packages/google/api_core/future/polling.py", line 86, in _done_or_raise
    if not self.done(**kwargs):
  File "/home/airflow/.local/lib/python3.7/site-packages/google/api_core/operation.py", line 170, in done
    self._refresh_and_update(retry)
  File "/home/airflow/.local/lib/python3.7/site-packages/google/api_core/operation.py", line 158, in _refresh_and_update
    self._operation = self._refresh(retry=retry)
  File "/home/airflow/.local/lib/python3.7/site-packages/google/api_core/operations_v1/operations_client.py", line 143, in get_operation
    request, retry=retry, timeout=timeout, metadata=metadata
  File "/home/airflow/.local/lib/python3.7/site-packages/google/api_core/gapic_v1/method.py", line 145, in __call__
    return wrapped_func(*args, **kwargs)
  File "/home/airflow/.local/lib/python3.7/site-packages/google/api_core/retry.py", line 291, in retry_wrapped_func
    on_error=on_error,
  File "/home/airflow/.local/lib/python3.7/site-packages/google/api_core/retry.py", line 189, in retry_target
    return target()
  File "/home/airflow/.local/lib/python3.7/site-packages/google/api_core/timeout.py", line 214, in func_with_timeout
    return func(*args, **kwargs)
  File "/home/airflow/.local/lib/python3.7/site-packages/google/api_core/grpc_helpers.py", line 69, in error_remapped_callable
    six.raise_from(exceptions.from_grpc_error(exc), exc)
  File "<string>", line 3, in raise_from
google.api_core.exceptions.DeadlineExceeded: 504 Deadline Exceeded
[2022-10-05 23:25:17,919] {taskinstance.py:1282} INFO - Marking task as FAILED. dag_id=dag_combustivel, task_id=create_cluster, execution_date=20180701T000000, start_date=20221005T231739, end_date=20221005T232517
[2022-10-05 23:25:18,056] {standard_task_runner.py:92} ERROR - Failed to execute job 158 for task create_cluster
Traceback (most recent call last):
  File "/home/airflow/.local/lib/python3.7/site-packages/google/api_core/grpc_helpers.py", line 67, in error_remapped_callable
    return callable_(*args, **kwargs)
  File "/home/airflow/.local/lib/python3.7/site-packages/grpc/_channel.py", line 946, in __call__
    return _end_unary_response_blocking(state, call, False, None)
  File "/home/airflow/.local/lib/python3.7/site-packages/grpc/_channel.py", line 849, in _end_unary_response_blocking
    raise _InactiveRpcError(state)
grpc._channel._InactiveRpcError: <_InactiveRpcError of RPC that terminated with:
	status = StatusCode.DEADLINE_EXCEEDED
	details = "Deadline Exceeded"
	debug_error_string = "{"created":"@1665012317.390874258","description":"Error received from peer ipv4:142.250.78.202:443","file":"src/core/lib/surface/call.cc","file_line":903,"grpc_message":"Deadline Exceeded","grpc_status":4}"
>

The above exception was the direct cause of the following exception:

Traceback (most recent call last):
  File "/home/airflow/.local/lib/python3.7/site-packages/airflow/task/task_runner/standard_task_runner.py", line 85, in _start_by_fork
    args.func(args, dag=self.dag)
  File "/home/airflow/.local/lib/python3.7/site-packages/airflow/cli/cli_parser.py", line 48, in command
    return func(*args, **kwargs)
  File "/home/airflow/.local/lib/python3.7/site-packages/airflow/utils/cli.py", line 92, in wrapper
    return f(*args, **kwargs)
  File "/home/airflow/.local/lib/python3.7/site-packages/airflow/cli/commands/task_command.py", line 298, in task_run
    _run_task_by_selected_method(args, dag, ti)
  File "/home/airflow/.local/lib/python3.7/site-packages/airflow/cli/commands/task_command.py", line 107, in _run_task_by_selected_method
    _run_raw_task(args, ti)
  File "/home/airflow/.local/lib/python3.7/site-packages/airflow/cli/commands/task_command.py", line 184, in _run_raw_task
    error_file=args.error_file,
  File "/home/airflow/.local/lib/python3.7/site-packages/airflow/utils/session.py", line 70, in wrapper
    return func(*args, session=session, **kwargs)
  File "/home/airflow/.local/lib/python3.7/site-packages/airflow/models/taskinstance.py", line 1334, in _run_raw_task
    self._execute_task_with_callbacks(context)
  File "/home/airflow/.local/lib/python3.7/site-packages/airflow/models/taskinstance.py", line 1460, in _execute_task_with_callbacks
    result = self._execute_task(context, self.task)
  File "/home/airflow/.local/lib/python3.7/site-packages/airflow/models/taskinstance.py", line 1516, in _execute_task
    result = execute_callable(context=context)
  File "/home/airflow/.local/lib/python3.7/site-packages/airflow/providers/google/cloud/operators/dataproc.py", line 639, in execute
    cluster = self._create_cluster(hook)
  File "/home/airflow/.local/lib/python3.7/site-packages/airflow/providers/google/cloud/operators/dataproc.py", line 568, in _create_cluster
    cluster = operation.result()
  File "/home/airflow/.local/lib/python3.7/site-packages/google/api_core/future/polling.py", line 130, in result
    self._blocking_poll(timeout=timeout, **kwargs)
  File "/home/airflow/.local/lib/python3.7/site-packages/google/api_core/future/polling.py", line 108, in _blocking_poll
    retry_(self._done_or_raise)(**kwargs)
  File "/home/airflow/.local/lib/python3.7/site-packages/google/api_core/retry.py", line 291, in retry_wrapped_func
    on_error=on_error,
  File "/home/airflow/.local/lib/python3.7/site-packages/google/api_core/retry.py", line 189, in retry_target
    return target()
  File "/home/airflow/.local/lib/python3.7/site-packages/google/api_core/future/polling.py", line 86, in _done_or_raise
    if not self.done(**kwargs):
  File "/home/airflow/.local/lib/python3.7/site-packages/google/api_core/operation.py", line 170, in done
    self._refresh_and_update(retry)
  File "/home/airflow/.local/lib/python3.7/site-packages/google/api_core/operation.py", line 158, in _refresh_and_update
    self._operation = self._refresh(retry=retry)
  File "/home/airflow/.local/lib/python3.7/site-packages/google/api_core/operations_v1/operations_client.py", line 143, in get_operation
    request, retry=retry, timeout=timeout, metadata=metadata
  File "/home/airflow/.local/lib/python3.7/site-packages/google/api_core/gapic_v1/method.py", line 145, in __call__
    return wrapped_func(*args, **kwargs)
  File "/home/airflow/.local/lib/python3.7/site-packages/google/api_core/retry.py", line 291, in retry_wrapped_func
    on_error=on_error,
  File "/home/airflow/.local/lib/python3.7/site-packages/google/api_core/retry.py", line 189, in retry_target
    return target()
  File "/home/airflow/.local/lib/python3.7/site-packages/google/api_core/timeout.py", line 214, in func_with_timeout
    return func(*args, **kwargs)
  File "/home/airflow/.local/lib/python3.7/site-packages/google/api_core/grpc_helpers.py", line 69, in error_remapped_callable
    six.raise_from(exceptions.from_grpc_error(exc), exc)
  File "<string>", line 3, in raise_from
google.api_core.exceptions.DeadlineExceeded: 504 Deadline Exceeded
[2022-10-05 23:25:18,196] {local_task_job.py:154} INFO - Task exited with return code 1
[2022-10-05 23:25:17,292] {local_task_job.py:264} INFO - 0 downstream tasks scheduled from follow-on schedule check
