[2022-10-05 13:05:59,996] {taskinstance.py:1037} INFO - Dependencies all met for <TaskInstance: dag_combustivel.get_op scheduled__2005-01-01T00:00:00+00:00 [queued]>
[2022-10-05 13:06:00,007] {taskinstance.py:1037} INFO - Dependencies all met for <TaskInstance: dag_combustivel.get_op scheduled__2005-01-01T00:00:00+00:00 [queued]>
[2022-10-05 13:06:00,008] {taskinstance.py:1243} INFO - 
--------------------------------------------------------------------------------
[2022-10-05 13:06:00,009] {taskinstance.py:1244} INFO - Starting attempt 1 of 1
[2022-10-05 13:06:00,010] {taskinstance.py:1245} INFO - 
--------------------------------------------------------------------------------
[2022-10-05 13:06:00,022] {taskinstance.py:1264} INFO - Executing <Task(SimpleHttpOperator): get_op> on 2005-01-01 00:00:00+00:00
[2022-10-05 13:06:00,027] {standard_task_runner.py:52} INFO - Started process 10858 to run task
[2022-10-05 13:06:00,032] {standard_task_runner.py:76} INFO - Running: ['***', 'tasks', 'run', 'dag_combustivel', 'get_op', 'scheduled__2005-01-01T00:00:00+00:00', '--job-id', '12', '--raw', '--subdir', 'DAGS_FOLDER/dag_combustive.py', '--cfg-path', '/tmp/tmppnsh3xqj', '--error-file', '/tmp/tmpo_eqwf2f']
[2022-10-05 13:06:00,034] {standard_task_runner.py:77} INFO - Job 12: Subtask get_op
[2022-10-05 13:06:00,101] {logging_mixin.py:109} INFO - Running <TaskInstance: dag_combustivel.get_op scheduled__2005-01-01T00:00:00+00:00 [running]> on host 1445d51ba90b
[2022-10-05 13:06:00,162] {taskinstance.py:1431} INFO - Exporting the following env vars:
AIRFLOW_CTX_DAG_OWNER=***
AIRFLOW_CTX_DAG_ID=dag_combustivel
AIRFLOW_CTX_TASK_ID=get_op
AIRFLOW_CTX_EXECUTION_DATE=2005-01-01T00:00:00+00:00
AIRFLOW_CTX_DAG_RUN_ID=scheduled__2005-01-01T00:00:00+00:00
[2022-10-05 13:06:00,163] {http.py:104} INFO - Calling HTTP method
[2022-10-05 13:06:00,185] {taskinstance.py:1718} ERROR - Task failed with exception
Traceback (most recent call last):
  File "/home/airflow/.local/lib/python3.7/site-packages/airflow/models/taskinstance.py", line 1334, in _run_raw_task
    self._execute_task_with_callbacks(context)
  File "/home/airflow/.local/lib/python3.7/site-packages/airflow/models/taskinstance.py", line 1460, in _execute_task_with_callbacks
    result = self._execute_task(context, self.task)
  File "/home/airflow/.local/lib/python3.7/site-packages/airflow/models/taskinstance.py", line 1516, in _execute_task
    result = execute_callable(context=context)
  File "/home/airflow/.local/lib/python3.7/site-packages/airflow/providers/http/operators/http.py", line 106, in execute
    response = http.run(self.endpoint, self.data, self.headers, self.extra_options)
  File "/home/airflow/.local/lib/python3.7/site-packages/airflow/providers/http/hooks/http.py", line 114, in run
    session = self.get_conn(headers)
  File "/home/airflow/.local/lib/python3.7/site-packages/airflow/providers/http/hooks/http.py", line 68, in get_conn
    conn = self.get_connection(self.http_conn_id)
  File "/home/airflow/.local/lib/python3.7/site-packages/airflow/hooks/base.py", line 68, in get_connection
    conn = Connection.get_connection_from_secrets(conn_id)
  File "/home/airflow/.local/lib/python3.7/site-packages/airflow/models/connection.py", line 410, in get_connection_from_secrets
    raise AirflowNotFoundException(f"The conn_id `{conn_id}` isn't defined")
airflow.exceptions.AirflowNotFoundException: The conn_id `api_data_challenge` isn't defined
[2022-10-05 13:06:00,207] {taskinstance.py:1282} INFO - Marking task as FAILED. dag_id=dag_combustivel, task_id=get_op, execution_date=20050101T000000, start_date=20221005T130559, end_date=20221005T130600
[2022-10-05 13:06:00,219] {standard_task_runner.py:92} ERROR - Failed to execute job 12 for task get_op
Traceback (most recent call last):
  File "/home/airflow/.local/lib/python3.7/site-packages/airflow/task/task_runner/standard_task_runner.py", line 85, in _start_by_fork
    args.func(args, dag=self.dag)
  File "/home/airflow/.local/lib/python3.7/site-packages/airflow/cli/cli_parser.py", line 48, in command
    return func(*args, **kwargs)
  File "/home/airflow/.local/lib/python3.7/site-packages/airflow/utils/cli.py", line 92, in wrapper
    return f(*args, **kwargs)
  File "/home/airflow/.local/lib/python3.7/site-packages/airflow/cli/commands/task_command.py", line 298, in task_run
    _run_task_by_selected_method(args, dag, ti)
  File "/home/airflow/.local/lib/python3.7/site-packages/airflow/cli/commands/task_command.py", line 107, in _run_task_by_selected_method
    _run_raw_task(args, ti)
  File "/home/airflow/.local/lib/python3.7/site-packages/airflow/cli/commands/task_command.py", line 184, in _run_raw_task
    error_file=args.error_file,
  File "/home/airflow/.local/lib/python3.7/site-packages/airflow/utils/session.py", line 70, in wrapper
    return func(*args, session=session, **kwargs)
  File "/home/airflow/.local/lib/python3.7/site-packages/airflow/models/taskinstance.py", line 1334, in _run_raw_task
    self._execute_task_with_callbacks(context)
  File "/home/airflow/.local/lib/python3.7/site-packages/airflow/models/taskinstance.py", line 1460, in _execute_task_with_callbacks
    result = self._execute_task(context, self.task)
  File "/home/airflow/.local/lib/python3.7/site-packages/airflow/models/taskinstance.py", line 1516, in _execute_task
    result = execute_callable(context=context)
  File "/home/airflow/.local/lib/python3.7/site-packages/airflow/providers/http/operators/http.py", line 106, in execute
    response = http.run(self.endpoint, self.data, self.headers, self.extra_options)
  File "/home/airflow/.local/lib/python3.7/site-packages/airflow/providers/http/hooks/http.py", line 114, in run
    session = self.get_conn(headers)
  File "/home/airflow/.local/lib/python3.7/site-packages/airflow/providers/http/hooks/http.py", line 68, in get_conn
    conn = self.get_connection(self.http_conn_id)
  File "/home/airflow/.local/lib/python3.7/site-packages/airflow/hooks/base.py", line 68, in get_connection
    conn = Connection.get_connection_from_secrets(conn_id)
  File "/home/airflow/.local/lib/python3.7/site-packages/airflow/models/connection.py", line 410, in get_connection_from_secrets
    raise AirflowNotFoundException(f"The conn_id `{conn_id}` isn't defined")
airflow.exceptions.AirflowNotFoundException: The conn_id `api_data_challenge` isn't defined
[2022-10-05 13:06:00,248] {local_task_job.py:154} INFO - Task exited with return code 1
[2022-10-05 13:06:00,302] {local_task_job.py:264} INFO - 0 downstream tasks scheduled from follow-on schedule check
[2022-11-02 00:34:19,936] {taskinstance.py:1037} INFO - Dependencies all met for <TaskInstance: dag_combustivel.get_op scheduled__2005-01-01T00:00:00+00:00 [queued]>
[2022-11-02 00:34:19,965] {taskinstance.py:1037} INFO - Dependencies all met for <TaskInstance: dag_combustivel.get_op scheduled__2005-01-01T00:00:00+00:00 [queued]>
[2022-11-02 00:34:19,966] {taskinstance.py:1243} INFO - 
--------------------------------------------------------------------------------
[2022-11-02 00:34:19,967] {taskinstance.py:1244} INFO - Starting attempt 1 of 1
[2022-11-02 00:34:19,969] {taskinstance.py:1245} INFO - 
--------------------------------------------------------------------------------
[2022-11-02 00:34:19,993] {taskinstance.py:1264} INFO - Executing <Task(SimpleHttpOperator): get_op> on 2005-01-01 00:00:00+00:00
[2022-11-02 00:34:19,999] {standard_task_runner.py:52} INFO - Started process 2297 to run task
[2022-11-02 00:34:20,006] {standard_task_runner.py:76} INFO - Running: ['***', 'tasks', 'run', 'dag_combustivel', 'get_op', 'scheduled__2005-01-01T00:00:00+00:00', '--job-id', '228', '--raw', '--subdir', 'DAGS_FOLDER/dag_combustivel.py', '--cfg-path', '/tmp/tmp3szknb19', '--error-file', '/tmp/tmpzzg54wjc']
[2022-11-02 00:34:20,011] {standard_task_runner.py:77} INFO - Job 228: Subtask get_op
[2022-11-02 00:34:20,119] {logging_mixin.py:109} INFO - Running <TaskInstance: dag_combustivel.get_op scheduled__2005-01-01T00:00:00+00:00 [running]> on host 44262508447e
[2022-11-02 00:34:20,211] {taskinstance.py:1431} INFO - Exporting the following env vars:
AIRFLOW_CTX_DAG_OWNER=***
AIRFLOW_CTX_DAG_ID=dag_combustivel
AIRFLOW_CTX_TASK_ID=get_op
AIRFLOW_CTX_EXECUTION_DATE=2005-01-01T00:00:00+00:00
AIRFLOW_CTX_DAG_RUN_ID=scheduled__2005-01-01T00:00:00+00:00
[2022-11-02 00:34:20,214] {http.py:104} INFO - Calling HTTP method
[2022-11-02 00:34:20,233] {base.py:79} INFO - Using connection to: id: stack-data-pipeline. Host: https://stack-gcp-data-pipeline-7lqmljbfeq-uc.a.run.app, Port: None, Schema: , Login: , Password: None, extra: {}
[2022-11-02 00:34:20,236] {http.py:129} INFO - Sending 'POST' to url: https://stack-gcp-data-pipeline-7lqmljbfeq-uc.a.run.app/download_combustivel
[2022-11-02 00:39:20,665] {http.py:142} ERROR - HTTP error: Gateway Timeout
[2022-11-02 00:39:20,669] {http.py:143} ERROR - upstream request timeout
[2022-11-02 00:39:20,711] {taskinstance.py:1718} ERROR - Task failed with exception
Traceback (most recent call last):
  File "/home/airflow/.local/lib/python3.7/site-packages/airflow/providers/http/hooks/http.py", line 140, in check_response
    response.raise_for_status()
  File "/home/airflow/.local/lib/python3.7/site-packages/requests/models.py", line 960, in raise_for_status
    raise HTTPError(http_error_msg, response=self)
requests.exceptions.HTTPError: 504 Server Error: Gateway Timeout for url: https://stack-gcp-data-pipeline-7lqmljbfeq-uc.a.run.app/download_combustivel

During handling of the above exception, another exception occurred:

Traceback (most recent call last):
  File "/home/airflow/.local/lib/python3.7/site-packages/airflow/models/taskinstance.py", line 1334, in _run_raw_task
    self._execute_task_with_callbacks(context)
  File "/home/airflow/.local/lib/python3.7/site-packages/airflow/models/taskinstance.py", line 1460, in _execute_task_with_callbacks
    result = self._execute_task(context, self.task)
  File "/home/airflow/.local/lib/python3.7/site-packages/airflow/models/taskinstance.py", line 1516, in _execute_task
    result = execute_callable(context=context)
  File "/home/airflow/.local/lib/python3.7/site-packages/airflow/providers/http/operators/http.py", line 106, in execute
    response = http.run(self.endpoint, self.data, self.headers, self.extra_options)
  File "/home/airflow/.local/lib/python3.7/site-packages/airflow/providers/http/hooks/http.py", line 130, in run
    return self.run_and_check(session, prepped_request, extra_options)
  File "/home/airflow/.local/lib/python3.7/site-packages/airflow/providers/http/hooks/http.py", line 183, in run_and_check
    self.check_response(response)
  File "/home/airflow/.local/lib/python3.7/site-packages/airflow/providers/http/hooks/http.py", line 144, in check_response
    raise AirflowException(str(response.status_code) + ":" + response.reason)
airflow.exceptions.AirflowException: 504:Gateway Timeout
[2022-11-02 00:39:20,740] {taskinstance.py:1282} INFO - Marking task as FAILED. dag_id=dag_combustivel, task_id=get_op, execution_date=20050101T000000, start_date=20221102T003419, end_date=20221102T003920
[2022-11-02 00:39:20,786] {standard_task_runner.py:92} ERROR - Failed to execute job 228 for task get_op
Traceback (most recent call last):
  File "/home/airflow/.local/lib/python3.7/site-packages/airflow/providers/http/hooks/http.py", line 140, in check_response
    response.raise_for_status()
  File "/home/airflow/.local/lib/python3.7/site-packages/requests/models.py", line 960, in raise_for_status
    raise HTTPError(http_error_msg, response=self)
requests.exceptions.HTTPError: 504 Server Error: Gateway Timeout for url: https://stack-gcp-data-pipeline-7lqmljbfeq-uc.a.run.app/download_combustivel

During handling of the above exception, another exception occurred:

Traceback (most recent call last):
  File "/home/airflow/.local/lib/python3.7/site-packages/airflow/task/task_runner/standard_task_runner.py", line 85, in _start_by_fork
    args.func(args, dag=self.dag)
  File "/home/airflow/.local/lib/python3.7/site-packages/airflow/cli/cli_parser.py", line 48, in command
    return func(*args, **kwargs)
  File "/home/airflow/.local/lib/python3.7/site-packages/airflow/utils/cli.py", line 92, in wrapper
    return f(*args, **kwargs)
  File "/home/airflow/.local/lib/python3.7/site-packages/airflow/cli/commands/task_command.py", line 298, in task_run
    _run_task_by_selected_method(args, dag, ti)
  File "/home/airflow/.local/lib/python3.7/site-packages/airflow/cli/commands/task_command.py", line 107, in _run_task_by_selected_method
    _run_raw_task(args, ti)
  File "/home/airflow/.local/lib/python3.7/site-packages/airflow/cli/commands/task_command.py", line 184, in _run_raw_task
    error_file=args.error_file,
  File "/home/airflow/.local/lib/python3.7/site-packages/airflow/utils/session.py", line 70, in wrapper
    return func(*args, session=session, **kwargs)
  File "/home/airflow/.local/lib/python3.7/site-packages/airflow/models/taskinstance.py", line 1334, in _run_raw_task
    self._execute_task_with_callbacks(context)
  File "/home/airflow/.local/lib/python3.7/site-packages/airflow/models/taskinstance.py", line 1460, in _execute_task_with_callbacks
    result = self._execute_task(context, self.task)
  File "/home/airflow/.local/lib/python3.7/site-packages/airflow/models/taskinstance.py", line 1516, in _execute_task
    result = execute_callable(context=context)
  File "/home/airflow/.local/lib/python3.7/site-packages/airflow/providers/http/operators/http.py", line 106, in execute
    response = http.run(self.endpoint, self.data, self.headers, self.extra_options)
  File "/home/airflow/.local/lib/python3.7/site-packages/airflow/providers/http/hooks/http.py", line 130, in run
    return self.run_and_check(session, prepped_request, extra_options)
  File "/home/airflow/.local/lib/python3.7/site-packages/airflow/providers/http/hooks/http.py", line 183, in run_and_check
    self.check_response(response)
  File "/home/airflow/.local/lib/python3.7/site-packages/airflow/providers/http/hooks/http.py", line 144, in check_response
    raise AirflowException(str(response.status_code) + ":" + response.reason)
airflow.exceptions.AirflowException: 504:Gateway Timeout
[2022-11-02 00:39:20,881] {local_task_job.py:154} INFO - Task exited with return code 1
[2022-11-02 00:39:21,007] {local_task_job.py:264} INFO - 0 downstream tasks scheduled from follow-on schedule check
