[2022-11-02 00:32:23,515] {taskinstance.py:1037} INFO - Dependencies all met for <TaskInstance: dag_combustivel.create_cluster scheduled__2004-01-01T00:00:00+00:00 [queued]>
[2022-11-02 00:32:23,532] {taskinstance.py:1037} INFO - Dependencies all met for <TaskInstance: dag_combustivel.create_cluster scheduled__2004-01-01T00:00:00+00:00 [queued]>
[2022-11-02 00:32:23,534] {taskinstance.py:1243} INFO - 
--------------------------------------------------------------------------------
[2022-11-02 00:32:23,535] {taskinstance.py:1244} INFO - Starting attempt 1 of 1
[2022-11-02 00:32:23,536] {taskinstance.py:1245} INFO - 
--------------------------------------------------------------------------------
[2022-11-02 00:32:23,553] {taskinstance.py:1264} INFO - Executing <Task(DataprocCreateClusterOperator): create_cluster> on 2004-01-01 00:00:00+00:00
[2022-11-02 00:32:23,558] {standard_task_runner.py:52} INFO - Started process 2209 to run task
[2022-11-02 00:32:23,564] {standard_task_runner.py:76} INFO - Running: ['***', 'tasks', 'run', 'dag_combustivel', 'create_cluster', 'scheduled__2004-01-01T00:00:00+00:00', '--job-id', '225', '--raw', '--subdir', 'DAGS_FOLDER/dag_combustivel.py', '--cfg-path', '/tmp/tmpnw36yw8c', '--error-file', '/tmp/tmpawqa70qf']
[2022-11-02 00:32:23,566] {standard_task_runner.py:77} INFO - Job 225: Subtask create_cluster
[2022-11-02 00:32:23,630] {logging_mixin.py:109} INFO - Running <TaskInstance: dag_combustivel.create_cluster scheduled__2004-01-01T00:00:00+00:00 [running]> on host 44262508447e
[2022-11-02 00:32:23,696] {taskinstance.py:1431} INFO - Exporting the following env vars:
AIRFLOW_CTX_DAG_OWNER=***
AIRFLOW_CTX_DAG_ID=dag_combustivel
AIRFLOW_CTX_TASK_ID=create_cluster
AIRFLOW_CTX_EXECUTION_DATE=2004-01-01T00:00:00+00:00
AIRFLOW_CTX_DAG_RUN_ID=scheduled__2004-01-01T00:00:00+00:00
[2022-11-02 00:32:23,698] {dataproc.py:625} INFO - Creating cluster: stack-data-pipeline
[2022-11-02 00:32:26,192] {taskinstance.py:1718} ERROR - Task failed with exception
Traceback (most recent call last):
  File "/home/airflow/.local/lib/python3.7/site-packages/google/api_core/grpc_helpers.py", line 67, in error_remapped_callable
    return callable_(*args, **kwargs)
  File "/home/airflow/.local/lib/python3.7/site-packages/grpc/_channel.py", line 946, in __call__
    return _end_unary_response_blocking(state, call, False, None)
  File "/home/airflow/.local/lib/python3.7/site-packages/grpc/_channel.py", line 849, in _end_unary_response_blocking
    raise _InactiveRpcError(state)
grpc._channel._InactiveRpcError: <_InactiveRpcError of RPC that terminated with:
	status = StatusCode.INVALID_ARGUMENT
	details = "Multiple validation errors:
 - Insufficient 'CPUS' quota. Requested 6.0, available 2.0.
 - Insufficient 'INSTANCES' quota. Requested 3.0, available 2.0.
 - Insufficient 'IN_USE_ADDRESSES' quota. Requested 3.0, available 1.0.
 - This request exceeds CPU quota. Some things to try: request fewer workers (a minimum of 2 is required), use smaller master and/or worker machine types (such as n1-standard-2)."
	debug_error_string = "{"created":"@1667349146.188264312","description":"Error received from peer ipv4:142.250.78.202:443","file":"src/core/lib/surface/call.cc","file_line":903,"grpc_message":"Multiple validation errors:\n - Insufficient 'CPUS' quota. Requested 6.0, available 2.0.\n - Insufficient 'INSTANCES' quota. Requested 3.0, available 2.0.\n - Insufficient 'IN_USE_ADDRESSES' quota. Requested 3.0, available 1.0.\n - This request exceeds CPU quota. Some things to try: request fewer workers (a minimum of 2 is required), use smaller master and/or worker machine types (such as n1-standard-2).","grpc_status":3}"
>

The above exception was the direct cause of the following exception:

Traceback (most recent call last):
  File "/home/airflow/.local/lib/python3.7/site-packages/airflow/models/taskinstance.py", line 1334, in _run_raw_task
    self._execute_task_with_callbacks(context)
  File "/home/airflow/.local/lib/python3.7/site-packages/airflow/models/taskinstance.py", line 1460, in _execute_task_with_callbacks
    result = self._execute_task(context, self.task)
  File "/home/airflow/.local/lib/python3.7/site-packages/airflow/models/taskinstance.py", line 1516, in _execute_task
    result = execute_callable(context=context)
  File "/home/airflow/.local/lib/python3.7/site-packages/airflow/providers/google/cloud/operators/dataproc.py", line 639, in execute
    cluster = self._create_cluster(hook)
  File "/home/airflow/.local/lib/python3.7/site-packages/airflow/providers/google/cloud/operators/dataproc.py", line 566, in _create_cluster
    metadata=self.metadata,
  File "/home/airflow/.local/lib/python3.7/site-packages/airflow/providers/google/common/hooks/base_google.py", line 433, in inner_wrapper
    return func(self, *args, **kwargs)
  File "/home/airflow/.local/lib/python3.7/site-packages/airflow/providers/google/cloud/hooks/dataproc.py", line 343, in create_cluster
    metadata=metadata,
  File "/home/airflow/.local/lib/python3.7/site-packages/google/cloud/dataproc_v1/services/cluster_controller/client.py", line 469, in create_cluster
    response = rpc(request, retry=retry, timeout=timeout, metadata=metadata,)
  File "/home/airflow/.local/lib/python3.7/site-packages/google/api_core/gapic_v1/method.py", line 145, in __call__
    return wrapped_func(*args, **kwargs)
  File "/home/airflow/.local/lib/python3.7/site-packages/google/api_core/timeout.py", line 102, in func_with_timeout
    return func(*args, **kwargs)
  File "/home/airflow/.local/lib/python3.7/site-packages/google/api_core/grpc_helpers.py", line 69, in error_remapped_callable
    six.raise_from(exceptions.from_grpc_error(exc), exc)
  File "<string>", line 3, in raise_from
google.api_core.exceptions.InvalidArgument: 400 Multiple validation errors:
 - Insufficient 'CPUS' quota. Requested 6.0, available 2.0.
 - Insufficient 'INSTANCES' quota. Requested 3.0, available 2.0.
 - Insufficient 'IN_USE_ADDRESSES' quota. Requested 3.0, available 1.0.
 - This request exceeds CPU quota. Some things to try: request fewer workers (a minimum of 2 is required), use smaller master and/or worker machine types (such as n1-standard-2).
[2022-11-02 00:32:26,222] {taskinstance.py:1282} INFO - Marking task as FAILED. dag_id=dag_combustivel, task_id=create_cluster, execution_date=20040101T000000, start_date=20221102T003223, end_date=20221102T003226
[2022-11-02 00:32:26,248] {standard_task_runner.py:92} ERROR - Failed to execute job 225 for task create_cluster
Traceback (most recent call last):
  File "/home/airflow/.local/lib/python3.7/site-packages/google/api_core/grpc_helpers.py", line 67, in error_remapped_callable
    return callable_(*args, **kwargs)
  File "/home/airflow/.local/lib/python3.7/site-packages/grpc/_channel.py", line 946, in __call__
    return _end_unary_response_blocking(state, call, False, None)
  File "/home/airflow/.local/lib/python3.7/site-packages/grpc/_channel.py", line 849, in _end_unary_response_blocking
    raise _InactiveRpcError(state)
grpc._channel._InactiveRpcError: <_InactiveRpcError of RPC that terminated with:
	status = StatusCode.INVALID_ARGUMENT
	details = "Multiple validation errors:
 - Insufficient 'CPUS' quota. Requested 6.0, available 2.0.
 - Insufficient 'INSTANCES' quota. Requested 3.0, available 2.0.
 - Insufficient 'IN_USE_ADDRESSES' quota. Requested 3.0, available 1.0.
 - This request exceeds CPU quota. Some things to try: request fewer workers (a minimum of 2 is required), use smaller master and/or worker machine types (such as n1-standard-2)."
	debug_error_string = "{"created":"@1667349146.188264312","description":"Error received from peer ipv4:142.250.78.202:443","file":"src/core/lib/surface/call.cc","file_line":903,"grpc_message":"Multiple validation errors:\n - Insufficient 'CPUS' quota. Requested 6.0, available 2.0.\n - Insufficient 'INSTANCES' quota. Requested 3.0, available 2.0.\n - Insufficient 'IN_USE_ADDRESSES' quota. Requested 3.0, available 1.0.\n - This request exceeds CPU quota. Some things to try: request fewer workers (a minimum of 2 is required), use smaller master and/or worker machine types (such as n1-standard-2).","grpc_status":3}"
>

The above exception was the direct cause of the following exception:

Traceback (most recent call last):
  File "/home/airflow/.local/lib/python3.7/site-packages/airflow/task/task_runner/standard_task_runner.py", line 85, in _start_by_fork
    args.func(args, dag=self.dag)
  File "/home/airflow/.local/lib/python3.7/site-packages/airflow/cli/cli_parser.py", line 48, in command
    return func(*args, **kwargs)
  File "/home/airflow/.local/lib/python3.7/site-packages/airflow/utils/cli.py", line 92, in wrapper
    return f(*args, **kwargs)
  File "/home/airflow/.local/lib/python3.7/site-packages/airflow/cli/commands/task_command.py", line 298, in task_run
    _run_task_by_selected_method(args, dag, ti)
  File "/home/airflow/.local/lib/python3.7/site-packages/airflow/cli/commands/task_command.py", line 107, in _run_task_by_selected_method
    _run_raw_task(args, ti)
  File "/home/airflow/.local/lib/python3.7/site-packages/airflow/cli/commands/task_command.py", line 184, in _run_raw_task
    error_file=args.error_file,
  File "/home/airflow/.local/lib/python3.7/site-packages/airflow/utils/session.py", line 70, in wrapper
    return func(*args, session=session, **kwargs)
  File "/home/airflow/.local/lib/python3.7/site-packages/airflow/models/taskinstance.py", line 1334, in _run_raw_task
    self._execute_task_with_callbacks(context)
  File "/home/airflow/.local/lib/python3.7/site-packages/airflow/models/taskinstance.py", line 1460, in _execute_task_with_callbacks
    result = self._execute_task(context, self.task)
  File "/home/airflow/.local/lib/python3.7/site-packages/airflow/models/taskinstance.py", line 1516, in _execute_task
    result = execute_callable(context=context)
  File "/home/airflow/.local/lib/python3.7/site-packages/airflow/providers/google/cloud/operators/dataproc.py", line 639, in execute
    cluster = self._create_cluster(hook)
  File "/home/airflow/.local/lib/python3.7/site-packages/airflow/providers/google/cloud/operators/dataproc.py", line 566, in _create_cluster
    metadata=self.metadata,
  File "/home/airflow/.local/lib/python3.7/site-packages/airflow/providers/google/common/hooks/base_google.py", line 433, in inner_wrapper
    return func(self, *args, **kwargs)
  File "/home/airflow/.local/lib/python3.7/site-packages/airflow/providers/google/cloud/hooks/dataproc.py", line 343, in create_cluster
    metadata=metadata,
  File "/home/airflow/.local/lib/python3.7/site-packages/google/cloud/dataproc_v1/services/cluster_controller/client.py", line 469, in create_cluster
    response = rpc(request, retry=retry, timeout=timeout, metadata=metadata,)
  File "/home/airflow/.local/lib/python3.7/site-packages/google/api_core/gapic_v1/method.py", line 145, in __call__
    return wrapped_func(*args, **kwargs)
  File "/home/airflow/.local/lib/python3.7/site-packages/google/api_core/timeout.py", line 102, in func_with_timeout
    return func(*args, **kwargs)
  File "/home/airflow/.local/lib/python3.7/site-packages/google/api_core/grpc_helpers.py", line 69, in error_remapped_callable
    six.raise_from(exceptions.from_grpc_error(exc), exc)
  File "<string>", line 3, in raise_from
google.api_core.exceptions.InvalidArgument: 400 Multiple validation errors:
 - Insufficient 'CPUS' quota. Requested 6.0, available 2.0.
 - Insufficient 'INSTANCES' quota. Requested 3.0, available 2.0.
 - Insufficient 'IN_USE_ADDRESSES' quota. Requested 3.0, available 1.0.
 - This request exceeds CPU quota. Some things to try: request fewer workers (a minimum of 2 is required), use smaller master and/or worker machine types (such as n1-standard-2).
[2022-11-02 00:32:26,279] {local_task_job.py:154} INFO - Task exited with return code 1
[2022-11-02 00:32:26,343] {local_task_job.py:264} INFO - 0 downstream tasks scheduled from follow-on schedule check
