[2022-11-16 21:10:19,488] {taskinstance.py:1037} INFO - Dependencies all met for <TaskInstance: dag_combustivel.pyspark_task manual__2022-11-16T21:07:34.027357+00:00 [queued]>
[2022-11-16 21:10:19,508] {taskinstance.py:1037} INFO - Dependencies all met for <TaskInstance: dag_combustivel.pyspark_task manual__2022-11-16T21:07:34.027357+00:00 [queued]>
[2022-11-16 21:10:19,509] {taskinstance.py:1243} INFO - 
--------------------------------------------------------------------------------
[2022-11-16 21:10:19,509] {taskinstance.py:1244} INFO - Starting attempt 1 of 1
[2022-11-16 21:10:19,510] {taskinstance.py:1245} INFO - 
--------------------------------------------------------------------------------
[2022-11-16 21:10:19,535] {taskinstance.py:1264} INFO - Executing <Task(DataprocSubmitJobOperator): pyspark_task> on 2022-11-16 21:07:34.027357+00:00
[2022-11-16 21:10:19,542] {standard_task_runner.py:52} INFO - Started process 704 to run task
[2022-11-16 21:10:19,550] {standard_task_runner.py:76} INFO - Running: ['***', 'tasks', 'run', 'dag_combustivel', 'pyspark_task', 'manual__2022-11-16T21:07:34.027357+00:00', '--job-id', '14', '--raw', '--subdir', 'DAGS_FOLDER/dag_combustivel.py', '--cfg-path', '/tmp/tmpjrv3fbc6', '--error-file', '/tmp/tmppl1ayqqb']
[2022-11-16 21:10:19,552] {standard_task_runner.py:77} INFO - Job 14: Subtask pyspark_task
[2022-11-16 21:10:19,642] {logging_mixin.py:109} INFO - Running <TaskInstance: dag_combustivel.pyspark_task manual__2022-11-16T21:07:34.027357+00:00 [running]> on host b2a62e76b908
[2022-11-16 21:10:19,765] {taskinstance.py:1431} INFO - Exporting the following env vars:
AIRFLOW_CTX_DAG_OWNER=***
AIRFLOW_CTX_DAG_ID=dag_combustivel
AIRFLOW_CTX_TASK_ID=pyspark_task
AIRFLOW_CTX_EXECUTION_DATE=2022-11-16T21:07:34.027357+00:00
AIRFLOW_CTX_DAG_RUN_ID=manual__2022-11-16T21:07:34.027357+00:00
[2022-11-16 21:10:19,767] {dataproc.py:1878} INFO - Submitting job
[2022-11-16 21:10:21,128] {taskinstance.py:1718} ERROR - Task failed with exception
Traceback (most recent call last):
  File "/home/airflow/.local/lib/python3.7/site-packages/google/api_core/grpc_helpers.py", line 67, in error_remapped_callable
    return callable_(*args, **kwargs)
  File "/home/airflow/.local/lib/python3.7/site-packages/grpc/_channel.py", line 946, in __call__
    return _end_unary_response_blocking(state, call, False, None)
  File "/home/airflow/.local/lib/python3.7/site-packages/grpc/_channel.py", line 849, in _end_unary_response_blocking
    raise _InactiveRpcError(state)
grpc._channel._InactiveRpcError: <_InactiveRpcError of RPC that terminated with:
	status = StatusCode.RESOURCE_EXHAUSTED
	details = "Multiple validation errors:
 - No agent on master node(s) found to be active in the past 300 seconds.
Last reported times: [stack-gcp-datapipeline-clusters-m seconds: 1667588389
nanos: 363741000
]
 - Unable to submit job, cluster 'stack-gcp-datapipeline-clusters' is in state STOPPED and cannot accept jobs."
	debug_error_string = "{"created":"@1668633021.126729200","description":"Error received from peer ipv4:142.251.135.138:443","file":"src/core/lib/surface/call.cc","file_line":903,"grpc_message":"Multiple validation errors:\n - No agent on master node(s) found to be active in the past 300 seconds.\nLast reported times: [stack-gcp-datapipeline-clusters-m seconds: 1667588389\nnanos: 363741000\n]\n - Unable to submit job, cluster 'stack-gcp-datapipeline-clusters' is in state STOPPED and cannot accept jobs.","grpc_status":8}"
>

The above exception was the direct cause of the following exception:

Traceback (most recent call last):
  File "/home/airflow/.local/lib/python3.7/site-packages/airflow/models/taskinstance.py", line 1334, in _run_raw_task
    self._execute_task_with_callbacks(context)
  File "/home/airflow/.local/lib/python3.7/site-packages/airflow/models/taskinstance.py", line 1460, in _execute_task_with_callbacks
    result = self._execute_task(context, self.task)
  File "/home/airflow/.local/lib/python3.7/site-packages/airflow/models/taskinstance.py", line 1516, in _execute_task
    result = execute_callable(context=context)
  File "/home/airflow/.local/lib/python3.7/site-packages/airflow/providers/google/cloud/operators/dataproc.py", line 1887, in execute
    metadata=self.metadata,
  File "/home/airflow/.local/lib/python3.7/site-packages/airflow/providers/google/common/hooks/base_google.py", line 433, in inner_wrapper
    return func(self, *args, **kwargs)
  File "/home/airflow/.local/lib/python3.7/site-packages/airflow/providers/google/cloud/hooks/dataproc.py", line 873, in submit_job
    metadata=metadata,
  File "/home/airflow/.local/lib/python3.7/site-packages/google/cloud/dataproc_v1/services/job_controller/client.py", line 421, in submit_job
    response = rpc(request, retry=retry, timeout=timeout, metadata=metadata,)
  File "/home/airflow/.local/lib/python3.7/site-packages/google/api_core/gapic_v1/method.py", line 145, in __call__
    return wrapped_func(*args, **kwargs)
  File "/home/airflow/.local/lib/python3.7/site-packages/google/api_core/grpc_helpers.py", line 69, in error_remapped_callable
    six.raise_from(exceptions.from_grpc_error(exc), exc)
  File "<string>", line 3, in raise_from
google.api_core.exceptions.ResourceExhausted: 429 Multiple validation errors:
 - No agent on master node(s) found to be active in the past 300 seconds.
Last reported times: [stack-gcp-datapipeline-clusters-m seconds: 1667588389
nanos: 363741000
]
 - Unable to submit job, cluster 'stack-gcp-datapipeline-clusters' is in state STOPPED and cannot accept jobs.
[2022-11-16 21:10:21,174] {taskinstance.py:1282} INFO - Marking task as FAILED. dag_id=dag_combustivel, task_id=pyspark_task, execution_date=20221116T210734, start_date=20221116T211019, end_date=20221116T211021
[2022-11-16 21:10:21,213] {standard_task_runner.py:92} ERROR - Failed to execute job 14 for task pyspark_task
Traceback (most recent call last):
  File "/home/airflow/.local/lib/python3.7/site-packages/google/api_core/grpc_helpers.py", line 67, in error_remapped_callable
    return callable_(*args, **kwargs)
  File "/home/airflow/.local/lib/python3.7/site-packages/grpc/_channel.py", line 946, in __call__
    return _end_unary_response_blocking(state, call, False, None)
  File "/home/airflow/.local/lib/python3.7/site-packages/grpc/_channel.py", line 849, in _end_unary_response_blocking
    raise _InactiveRpcError(state)
grpc._channel._InactiveRpcError: <_InactiveRpcError of RPC that terminated with:
	status = StatusCode.RESOURCE_EXHAUSTED
	details = "Multiple validation errors:
 - No agent on master node(s) found to be active in the past 300 seconds.
Last reported times: [stack-gcp-datapipeline-clusters-m seconds: 1667588389
nanos: 363741000
]
 - Unable to submit job, cluster 'stack-gcp-datapipeline-clusters' is in state STOPPED and cannot accept jobs."
	debug_error_string = "{"created":"@1668633021.126729200","description":"Error received from peer ipv4:142.251.135.138:443","file":"src/core/lib/surface/call.cc","file_line":903,"grpc_message":"Multiple validation errors:\n - No agent on master node(s) found to be active in the past 300 seconds.\nLast reported times: [stack-gcp-datapipeline-clusters-m seconds: 1667588389\nnanos: 363741000\n]\n - Unable to submit job, cluster 'stack-gcp-datapipeline-clusters' is in state STOPPED and cannot accept jobs.","grpc_status":8}"
>

The above exception was the direct cause of the following exception:

Traceback (most recent call last):
  File "/home/airflow/.local/lib/python3.7/site-packages/airflow/task/task_runner/standard_task_runner.py", line 85, in _start_by_fork
    args.func(args, dag=self.dag)
  File "/home/airflow/.local/lib/python3.7/site-packages/airflow/cli/cli_parser.py", line 48, in command
    return func(*args, **kwargs)
  File "/home/airflow/.local/lib/python3.7/site-packages/airflow/utils/cli.py", line 92, in wrapper
    return f(*args, **kwargs)
  File "/home/airflow/.local/lib/python3.7/site-packages/airflow/cli/commands/task_command.py", line 298, in task_run
    _run_task_by_selected_method(args, dag, ti)
  File "/home/airflow/.local/lib/python3.7/site-packages/airflow/cli/commands/task_command.py", line 107, in _run_task_by_selected_method
    _run_raw_task(args, ti)
  File "/home/airflow/.local/lib/python3.7/site-packages/airflow/cli/commands/task_command.py", line 184, in _run_raw_task
    error_file=args.error_file,
  File "/home/airflow/.local/lib/python3.7/site-packages/airflow/utils/session.py", line 70, in wrapper
    return func(*args, session=session, **kwargs)
  File "/home/airflow/.local/lib/python3.7/site-packages/airflow/models/taskinstance.py", line 1334, in _run_raw_task
    self._execute_task_with_callbacks(context)
  File "/home/airflow/.local/lib/python3.7/site-packages/airflow/models/taskinstance.py", line 1460, in _execute_task_with_callbacks
    result = self._execute_task(context, self.task)
  File "/home/airflow/.local/lib/python3.7/site-packages/airflow/models/taskinstance.py", line 1516, in _execute_task
    result = execute_callable(context=context)
  File "/home/airflow/.local/lib/python3.7/site-packages/airflow/providers/google/cloud/operators/dataproc.py", line 1887, in execute
    metadata=self.metadata,
  File "/home/airflow/.local/lib/python3.7/site-packages/airflow/providers/google/common/hooks/base_google.py", line 433, in inner_wrapper
    return func(self, *args, **kwargs)
  File "/home/airflow/.local/lib/python3.7/site-packages/airflow/providers/google/cloud/hooks/dataproc.py", line 873, in submit_job
    metadata=metadata,
  File "/home/airflow/.local/lib/python3.7/site-packages/google/cloud/dataproc_v1/services/job_controller/client.py", line 421, in submit_job
    response = rpc(request, retry=retry, timeout=timeout, metadata=metadata,)
  File "/home/airflow/.local/lib/python3.7/site-packages/google/api_core/gapic_v1/method.py", line 145, in __call__
    return wrapped_func(*args, **kwargs)
  File "/home/airflow/.local/lib/python3.7/site-packages/google/api_core/grpc_helpers.py", line 69, in error_remapped_callable
    six.raise_from(exceptions.from_grpc_error(exc), exc)
  File "<string>", line 3, in raise_from
google.api_core.exceptions.ResourceExhausted: 429 Multiple validation errors:
 - No agent on master node(s) found to be active in the past 300 seconds.
Last reported times: [stack-gcp-datapipeline-clusters-m seconds: 1667588389
nanos: 363741000
]
 - Unable to submit job, cluster 'stack-gcp-datapipeline-clusters' is in state STOPPED and cannot accept jobs.
[2022-11-16 21:10:21,251] {local_task_job.py:154} INFO - Task exited with return code 1
[2022-11-16 21:10:21,325] {local_task_job.py:264} INFO - 0 downstream tasks scheduled from follow-on schedule check
